Workbook
Name Slicer_City: #N/A
Name Slicer_Department: #N/A
Name Slicer_Source: #N/A
Name Slicer_Status: #N/A

Sheet Raw Data1
A1: Applicant ID | B1: Candidate Name | C1: City | D1: Department | E1: Job Role | F1: Source | G1: Status | H1: Application Date | I1: Salary Expected | J1: Experience
A2: 3101001 | B2: Arun | C2: Bangalore | D2: IT | E2: Data Analyst | F2: Naukri | G2: Selected | H2: 46027 | I2: 450000 | J2: 1
A3: 3101002 | B3: Priya | C3: Chennai | D3: HR | E3: HR Executive | F3: Employee Referral | G3: Interview | H3: 46034 | I3: 380000 | J3: 2
A4: 3101003 | B4: Rahul | C4: Bangalore | D4: IT | E4: Python Developer | F4: LinkedIn | G4: Rejected | H4: 46040 | I4: 500000 | J4: 1
A5: 3101004 | B5: Divya | C5: Hyderabad | D5: Finance | E5: MIS Executive | F5: Naukri | G5: Selected | H5: 46043 | I5: 350000 | J5: 2
A6: 3101005 | B6: Karthik | C6: Bangalore | D6: IT | E6: Data Analyst | F6: Employee Referral | G6: Interview | H6: 46047 | I6: 420000 | J6: 1
A7: 3101006 | B7: Sneha | C7: Chennai | D7: Operations | E7: Operations Executive | F7: Indeed | G7: Rejected | H7: 46055 | I7: 320000 | J7: 2
A8: 3101007 | B8: Ajay | C8: Bangalore | D8: IT | E8: ML Engineer | F8: LinkedIn | G8: Interview | H8: 46061 | I8: 600000 | J8: 1
A9: 3101008 | B9: Meena | C9: Pune | D9: HR | E9: Recruiter | F9: Employee Referral | G9: Selected | H9: 46067 | I9: 400000 | J9: 3
A10: 3101009 | B10: Rohit | C10: Bangalore | D10: Finance | E10: MIS Executive | F10: Naukri | G10: Rejected | H10: 46073 | I10: 360000 | J10: 1
A11: 3101010 | B11: Anjali | C11: Hyderabad | D11: IT | E11: Data Analyst | F11: LinkedIn | G11: Selected | H11: 46078 | I11: 480000 | J11: 2
A12: 3101011 | B12: Suresh | C12: Chennai | D12: IT | E12: Python Developer | F12: Naukri | G12: Interview | H12: 46083 | I12: 520000 | J12: 2
A13: 3101012 | B13: Kavya | C13: Bangalore | D13: HR | E13: HR Executive | F13: Indeed | G13: Rejected | H13: 46091 | I13: 370000 | J13: 1
... A477: 3101442 | B477: Madhavan | C477: Delhi | D477: HR | E477: HR Executive | F477: LinkedIn | G477: Interview | H477: 46179 | I477: 405000 | J477: 3

Sheet Data
A1: Applicant ID | B1: Candidate Name | C1: City | D1: Department | E1: Job Role | F1: Source | G1: Status | H1: Application Date | I1: Salary Expected | J1: Experience | K1: Performance | L1: Experience Category | M1: Salary Category | N1: Incentives | O1: Duplicate Flag | P1: Month
A2: 3101001 | B2: Arun | C2: Bangalore | D2: IT | E2: Data Analyst | F2: Naukri | G2: Selected | H2: 46027 | I2: 450000 | J2: 1 | K2: 82 | L2: {=_xlfn.IFS(J2<2,"Fresher",J2<=3,"Mid Level",J2>3,"Experienced")} -> Fresher | M2: {=_xlfn.IFS(I2>=600000,"High",I2>=450000,"Medium",I2<450000,"Low")} -> Medium | N2: =IF(F2="Naukri",2%,IF(F2="LinkedIn",2%,IF(F2="Employee Referral",5%,1%))) -> 0.02 | O2: =IF(COUNTIF($A$2:$A$478,A2)>1,"Duplicate","Unique") -> Unique | P2: =MONTH(H2) -> 1
A3: 3101002 | B3: Priya | C3: Chennai | D3: HR | E3: HR Executive | F3: Employee Referral | G3: Interview | H3: 46034 | I3: 380000 | J3: 2 | K3: 76 | L3: {=_xlfn.IFS(J3<2,"Fresher",J3<=3,"Mid Level",J3>3,"Experienced")} -> Mid Level | M3: {=_xlfn.IFS(I3>=600000,"High",I3>=450000,"Medium",I3<450000,"Low")} -> Low | N3: =IF(F3="Naukri",2%,IF(F3="LinkedIn",2%,IF(F3="Employee Referral",5%,1%))) -> 0.05 | O3: =IF(COUNTIF($A$2:$A$478,A3)>1,"Duplicate","Unique") -> Unique | P3: =MONTH(H3) -> 1
A4: 3101003 | B4: Rahul | C4: Bangalore | D4: IT | E4: Python Developer | F4: LinkedIn | G4: Rejected | H4: 46040 | I4: 500000 | J4: 1 | K4: 88 | L4: {=_xlfn.IFS(J4<2,"Fresher",J4<=3,"Mid Level",J4>3,"Experienced")} -> Fresher | M4: {=_xlfn.IFS(I4>=600000,"High",I4>=450000,"Medium",I4<450000,"Low")} -> Medium | N4: =IF(F4="Naukri",2%,IF(F4="LinkedIn",2%,IF(F4="Employee Referral",5%,1%))) -> 0.02 | O4: =IF(COUNTIF($A$2:$A$478,A4)>1,"Duplicate","Unique") -> Unique | P4: =MONTH(H4) -> 1
A5: 3101004 | B5: Divya | C5: Hyderabad | D5: Finance | E5: MIS Executive | F5: Naukri | G5: Selected | H5: 46043 | I5: 350000 | J5: 2 | K5: 91 | L5: {=_xlfn.IFS(J5<2,"Fresher",J5<=3,"Mid Level",J5>3,"Experienced")} -> Mid Level | M5: {=_xlfn.IFS(I5>=600000,"High",I5>=450000,"Medium",I5<450000,"Low")} -> Low | N5: =IF(F5="Naukri",2%,IF(F5="LinkedIn",2%,IF(F5="Employee Referral",5%,1%))) -> 0.02 | O5: =IF(COUNTIF($A$2:$A$478,A5)>1,"Duplicate","Unique") -> Unique | P5: =MONTH(H5) -> 1
A6: 3101005 | B6: Karthik | C6: Bangalore | D6: IT | E6: Data Analyst | F6: Employee Referral | G6: Interview | H6: 46046 | I6: 420000 | J6: 1 | K6: 69 | L6: {=_xlfn.IFS(J6<2,"Fresher",J6<=3,"Mid Level",J6>3,"Experienced")} -> Fresher | M6: {=_xlfn.IFS(I6>=600000,"High",I6>=450000,"Medium",I6<450000,"Low")} -> Low | N6: =IF(F6="Naukri",2%,IF(F6="LinkedIn",2%,IF(F6="Employee Referral",5%,1%))) -> 0.05 | O6: =IF(COUNTIF($A$2:$A$478,A6)>1,"Duplicate","Unique") -> Duplicate | P6: =MONTH(H6) -> 1
A7: 3101005 | B7: Karthik | C7: Bangalore | D7: IT | E7: Data Analyst | F7: Employee Referral | G7: Interview | H7: 46047 | I7: 420000 | J7: 1 | K7: 95 | L7: {=_xlfn.IFS(J7<2,"Fresher",J7<=3,"Mid Level",J7>3,"Experienced")} -> Fresher | M7: {=_xlfn.IFS(I7>=600000,"High",I7>=450000,"Medium",I7<450000,"Low")} -> Low | N7: =IF(F7="Naukri",2%,IF(F7="LinkedIn",2%,IF(F7="Employee Referral",5%,1%))) -> 0.05 | O7: =IF(COUNTIF($A$2:$A$478,A7)>1,"Duplicate","Unique") -> Duplicate | P7: =MONTH(H7) -> 1
A8: 3101006 | B8: Sneha | C8: Chennai | D8: Operations | E8: Operations Executive | F8: Indeed | G8: Rejected | H8: 46055 | I8: 320000 | J8: 2 | K8: 73 | L8: {=_xlfn.IFS(J8<2,"Fresher",J8<=3,"Mid Level",J8>3,"Experienced")} -> Mid Level | M8: {=_xlfn.IFS(I8>=600000,"High",I8>=450000,"Medium",I8<450000,"Low")} -> Low | N8: =IF(F8="Naukri",2%,IF(F8="LinkedIn",2%,IF(F8="Employee Referral",5%,1%))) -> 0.01 | O8: =IF(COUNTIF($A$2:$A$478,A8)>1,"Duplicate","Unique") -> Unique | P8: =MONTH(H8) -> 2
A9: 3101007 | B9: Ajay | C9: Bangalore | D9: IT | E9: ML Engineer | F9: LinkedIn | G9: Interview | H9: 46061 | I9: 600000 | J9: 1 | K9: 84 | L9: {=_xlfn.IFS(J9<2,"Fresher",J9<=3,"Mid Level",J9>3,"Experienced")} -> Fresher | M9: {=_xlfn.IFS(I9>=600000,"High",I9>=450000,"Medium",I9<450000,"Low")} -> High | N9: =IF(F9="Naukri",2%,IF(F9="LinkedIn",2%,IF(F9="Employee Referral",5%,1%))) -> 0.02 | O9: =IF(COUNTIF($A$2:$A$478,A9)>1,"Duplicate","Unique") -> Unique | P9: =MONTH(H9) -> 2
A10: 3101008 | B10: Meena | C10: Pune | D10: HR | E10: Recruiter | F10: Employee Referral | G10: Selected | H10: 46067 | I10: 400000 | J10: 3 | K10: 79 | L10: {=_xlfn.IFS(J10<2,"Fresher",J10<=3,"Mid Level",J10>3,"Experienced")} -> Mid Level | M10: {=_xlfn.IFS(I10>=600000,"High",I10>=450000,"Medium",I10<450000,"Low")} -> Low | N10: =IF(F10="Naukri",2%,IF(F10="LinkedIn",2%,IF(F10="Employee Referral",5%,1%))) -> 0.05 | O10: =IF(COUNTIF($A$2:$A$478,A10)>1,"Duplicate","Unique") -> Unique | P10: =MONTH(H10) -> 2
A11: 3101009 | B11: Rohit | C11: Bangalore | D11: Finance | E11: MIS Executive | F11: Naukri | G11: Rejected | H11: 46073 | I11: 360000 | J11: 1 | K11: 71 | L11: {=_xlfn.IFS(J11<2,"Fresher",J11<=3,"Mid Level",J11>3,"Experienced")} -> Fresher | M11: {=_xlfn.IFS(I11>=600000,"High",I11>=450000,"Medium",I11<450000,"Low")} -> Low | N11: =IF(F11="Naukri",2%,IF(F11="LinkedIn",2%,IF(F11="Employee Referral",5%,1%))) -> 0.02 | O11: =IF(COUNTIF($A$2:$A$478,A11)>1,"Duplicate","Unique") -> Unique | P11: =MONTH(H11) -> 2
A12: 3101010 | B12: Anjali | C12: Hyderabad | D12: IT | E12: Data Analyst | F12: LinkedIn | G12: Selected | H12: 46078 | I12: 480000 | J12: 2 | K12: 89 | L12: {=_xlfn.IFS(J12<2,"Fresher",J12<=3,"Mid Level",J12>3,"Experienced")} -> Mid Level | M12: {=_xlfn.IFS(I12>=600000,"High",I12>=450000,"Medium",I12<450000,"Low")} -> Medium | N12: =IF(F12="Naukri",2%,IF(F12="LinkedIn",2%,IF(F12="Employee Referral",5%,1%))) -> 0.02 | O12: =IF(COUNTIF($A$2:$A$478,A12)>1,"Duplicate","Unique") -> Unique | P12: =MONTH(H12) -> 2
A13: 3101011 | B13: Suresh | C13: Chennai | D13: IT | E13: Python Developer | F13: Naukri | G13: Interview | H13: 46083 | I13: 520000 | J13: 2 | K13: 67 | L13: {=_xlfn.IFS(J13<2,"Fresher",J13<=3,"Mid Level",J13>3,"Experienced")} -> Mid Level | M13: {=_xlfn.IFS(I13>=600000,"High",I13>=450000,"Medium",I13<450000,"Low")} -> Medium | N13: =IF(F13="Naukri",2%,IF(F13="LinkedIn",2%,IF(F13="Employee Referral",5%,1%))) -> 0.02 | O13: =IF(COUNTIF($A$2:$A$478,A13)>1,"Duplicate","Unique") -> Unique | P13: =MONTH(H13) -> 3
... A478: 3101442 | B478: Madhavan | C478: Delhi | D478: HR | E478: HR Executive | F478: LinkedIn | G478: Interview | H478: 46179 | I478: 405000 | J478: 3 | K478: 69 | L478: {=_xlfn.IFS(J478<2,"Fresher",J478<=3,"Mid Level",J478>3,"Experienced")} -> Mid Level | M478: {=_xlfn.IFS(I478>=600000,"High",I478>=450000,"Medium",I478<450000,"Low")} -> Low | N478: =IF(F478="Naukri",2%,IF(F478="LinkedIn",2%,IF(F478="Employee Referral",5%,1%))) -> 0.02 | O478: =IF(COUNTIF($A$2:$A$478,A478)>1,"Duplicate","Unique") -> Duplicate | P478: =MONTH(H478) -> 6

Sheet Dashboard
B2: HR Workforce Analytics Dashboard
B3: Excel practice project • Recruitment, workforce, salary and hiring insights
B5: Total Applicants | D5: Joined | F5: Pending | H5: Rejected | J5: Duplicate Records
B6: =COUNTA('Raw Data1'!A2:A478) -> 476 | D6: =COUNTIF('Raw Data1'!G2:G478,"Selected") -> 111 | F6: =COUNTIF('Raw Data1'!G2:G478,"Interview") -> 163 | H6: =COUNTIF('Raw Data1'!G2:G478,"Rejected") -> 118 | J6: =COUNTIF('Exercise 1-5'!G76:G104,"Duplicate") -> 16
B9: Key Metrics
B10: Average Salary | C10: =AVERAGE(Data!I2:I478) -> 513301.89
B11: Average Experience | C11: =AVERAGE(Data!J2:J478) -> 2.5136268
B12: Average Performance | C12: =AVERAGE(Data!K2:K478) -> 81.280977
B13: Highest Salary | C13: =MAX(Data!I1:I478) -> 895000

Sheet Chart Analysis
A3: Row Labels | B3: Count of Applicant ID
A4: Bangalore | B4: 69
A5: Chennai | B5: 64
A6: Coimbatore | B6: 51
A7: Delhi | B7: 59
A8: Hyderabad | B8: 48
A9: Kochi | B9: 61
A10: Mumbai | B10: 74
A11: Pune | B11: 51
A12: Grand Total | B12: 477
A20: Row Labels | B20: Avg of Salary Expected
A21: Finance | B21: 458098.59
A22: HR | B22: 416168.83
A23: IT | B23: 596557.69
A24: Operations | B24: 364782.61
A25: Grand Total | B25: 513301.89
A31: Status | B31: (All)
A33: Row Labels | B33: Count of Applicant ID
A34: Business Analyst | B34: 41
A35: Data Analyst | B35: 58
A36: Data Scientist | B36: 47
A37: Financial Analyst | B37: 39
A38: HR Executive | B38: 34
A39: MIS Executive | B39: 32
A40: ML Engineer | B40: 30
A41: Operations Executive | B41: 42
A42: Process Associate | B42: 27
A43: Python Developer | B43: 39
A44: Recruiter | B44: 43
A45: Software Developer | B45: 45
A46: Grand Total | B46: 477
A51: Row Labels | B51: Count of Incentives
A52: Employee Referral | B52: 118
A53: Indeed | B53: 111
A54: LinkedIn | B54: 126
A55: Naukri | B55: 122
A56: Grand Total | B56: 477
A60: Row Labels | B60: Count of Applicant ID
A61: Applied | B61: 84
A62: Interview | B62: 164
...

Sheet Exercise 1-5
A2: Exercise 1 — COUNTIF / COUNTIFS
A4: Q1
A6: Count the total number of applicants. | E6: =COUNT('Raw Data1'!A2:A477) -> 476
A8: Q2
A10: Count applicants from Bangalore. | D10: =COUNTIF('Raw Data1'!C2:C477,'Raw Data1'!C17) -> 68
A12: Q3
A14: Count applicants from Bangalore whose Status is Selected. | F14: =COUNTIFS('Raw Data1'!C2:C477,'Raw Data1'!C6,'Raw Data1'!G2:G477,'Raw Data1'!G5) -> 17
A16: Q4
A18: Count applicants whose Source is Employee Referral. | E18: =COUNTIF('Raw Data1'!$F$2:$F$477,'Raw Data1'!$F$3) -> 117
A20: Q5
A22: Count applicants from IT department with Interview status. | E22: =COUNTIFS('Raw Data1'!D2:D477,'Raw Data1'!D2,'Raw Data1'!G2:G477,'Raw Data1'!$G$3) -> 89
A24: Q6
A26: Count applicants with more than 1 year of experience. | E26: =COUNTIF(HR_Data[Experience],">1") -> 316
A28: Exercise 2 — IF
A30: Rules:
A32: Experience >= 2 → "Experienced"
A33: Experience < 2 → "Fresher"
A35: Q7
A39: Exercise 3 — IFS
A40: Salary Category
A42: Q8
A44: Expected Salary | B44: Category
A45: >= 600000 | B45: High
A46: >= 450000 | B46: Medium
A47: < 450000 | B47: Low
A49: Exercise 4 — Source of Hire Incentive
A50: Referral Incentive
A52: Q9
A54: Employee Referral → 5%
A55: Naukri → 2%
A56: LinkedIn → 2%
A57: Any other source → 1%
A59: Exercise 5 — Duplicate Detection
A61: Create:
A63: Duplicate Flag
A65: Use a COUNTIF-based IF formula.
A67: Q10
... A72: Appears once → Unique
B74: There is intentionally a duplicate Applicant ID in the dataset.
B75: Applicant ID | C75: Candidate Name | D75: Job ID | E75: Application Date | F75: Status | G75: Duplicate Flag
...

Sheet Ecercise 6-10
A2: Exercise 6 — Data Validation
A3: Q11
A4: Apply Data Validation dropdowns to the relevant columns.
B6: Status | C6: Department | D6: Source
A9: Exercise 7 — Conditional Formatting
A11: Q12
A13: Highlight:
A15: 1. Applicants with Selected status.
A16: 2. Applicants with salary expected >= ₹600,000.
A17: 3. Duplicate Applicant IDs.
B19: Applicant ID | C19: Candidate Name | D19: Job ID | E19: Application Date | F19: Status | G19: Salary Expected
B20: 4100001 | C20: Arjun | D20: 90101 | E20: 46027 | F20: Selected | G20: 450000
B21: 4100002 | C21: Priya | D21: 90105 | E21: 46030 | F21: Interview | G21: 380000
B22: 4100003 | C22: Rahul | D22: 90108 | E22: 46034 | F22: Rejected | G22: 500000
B23: 4100004 | C23: Divya | D23: 90112 | E23: 46037 | F23: Open | G23: 350000
B24: 4100005 | C24: Karthik | D24: 90115 | E24: 46040 | F24: Selected | G24: 420000
B25: 4100006 | C25: Sneha | D25: 90119 | E25: 46044 | F25: Interview | G25: 320000
B26: 4100003 | C26: Rahul | D26: 90125 | E26: 46047 | F26: Interview | G26: 600000
B27: 4100007 | C27: Ajay | D27: 90128 | E27: 46050 | F27: Rejected | G27: 400000
B28: 4100008 | C28: Meena | D28: 90131 | E28: 46055 | F28: Selected | G28: 360000
B29: 4100009 | C29: Rohit | D29: 90135 | E29: 46058 | F29: Open | G29: 480000
B30: 4100005 | C30: Karthik | D30: 90139 | E30: 46062 | F30: Rejected | G30: 520000
B31: 4100010 | C31: Anjali | D31: 90142 | E31: 46065 | F31: Interview | G31: 370000
... B48: 4100021 | C48: Deepa | D48: 90208 | E48: 46132 | F48: Rejected | G48: 340000
A50: Exercise 8 — SUMIFS
A52: Q13
A54: Calculate the total expected salary for Bangalore applicants. | E54: =SUMIFS('Raw Data1'!I2:I21,'Raw Data1'!C2:C21,'Raw Data1'!$C$2) -> 4290000
A56: Q14
A58: Calculate the total expected salary for:
B59: IT+Selected : | C59: =SUMIFS('Raw Data1'!$I$2:$I$21,'Raw Data1'!D2:D21,'Raw Data1'!$D$2,'Raw Data1'!G2:G21,'Raw Data1'!$G$2) -> 2030000
A60: Q15
A62: Calculate the total expected salary for:
A64: Employee Referral + Selected | C64: =SUMIFS('Raw Data1'!I2:I21,'Raw Data1'!F2:F21,'Raw Data1'!$F$3,'Raw Data1'!G2:G21,'Raw Data1'!$G$2) -> 400000
A66: Exercise 9 — AVERAGEIFS
A68: Q16
A70: Find the average expected salary of Bangalore applicants. | E70: =AVERAGEIF('Raw Data1'!C2:C21,'Raw Data1'!$C$2,'Raw Data1'!I2:I21) -> 429000
A72: Q17
A74: Find the average expected salary of IT applicants with Interview status. | F74: =AVERAGEIFS('Raw Data1'!I2:I21,'Raw Data1'!G2:G21,'Raw Data1'!$G$3,'Raw Data1'!D2:D21,'Raw Data1'!$D$2) -> 488000
A76: Exercise 10 — Date Functions
A78: Create a column:
...

Sheet Raw Data2
A1: Employee ID | B1: Employee Name | C1: City | D1: Department | E1: Source | F1: Status | G1: Joining Date | H1: Salary | I1: Experience | J1: Performance
A2: 5001 | B2: Anu | C2: Bangalore | D2: IT | E2: Naukri | F2: Joined | G2: 46027 | H2: 420000 | I2: 1 | J2: 82
A3: 5002 | B3: Rahul | C3: Chennai | D3: Finance | E3: Referral | F3: Joined | G3: 46034 | H3: 380000 | I3: 2 | J3: 76
A4: 5003 | B4: Priya | C4: Bangalore | D4: HR | E4: LinkedIn | F4: Pending | G4: 46040 | H4: 350000 | I4: 1 | J4: 88
A5: 5004 | B5: Kiran | C5: Hyderabad | D5: IT | E5: Naukri | F5: Joined | G5: 46044 | H5: 550000 | I5: 3 | J5: 91
A6: 5005 | B6: Sneha | C6: Bangalore | D6: Finance | E6: Referral | F6: Rejected | G6: 46051 | H6: 400000 | I6: 2 | J6: 69
A7: 5006 | B7: Arjun | C7: Pune | D7: IT | E7: LinkedIn | F7: Joined | G7: 46056 | H7: 600000 | I7: 4 | J7: 95
A8: 5007 | B8: Divya | C8: Bangalore | D8: Operations | E8: Walk-in | F8: Pending | G8: 46063 | H8: 320000 | I8: 1 | J8: 73
A9: 5008 | B9: Manoj | C9: Chennai | D9: IT | E9: Naukri | F9: Joined | G9: 46070 | H9: 480000 | I9: 2 | J9: 84
A10: 5009 | B10: Kavya | C10: Bangalore | D10: HR | E10: Referral | F10: Joined | G10: 46077 | H10: 390000 | I10: 2 | J10: 79
A11: 5010 | B11: Suresh | C11: Hyderabad | D11: Finance | E11: LinkedIn | F11: Rejected | G11: 46084 | H11: 450000 | I11: 3 | J11: 71
A12: 5011 | B12: Meena | C12: Bangalore | D12: IT | E12: Naukri | F12: Joined | G12: 46092 | H12: 520000 | I12: 1 | J12: 89
A13: 5012 | B13: Ajay | C13: Pune | D13: Operations | E13: Referral | F13: Pending | G13: 46099 | H13: 340000 | I13: 2 | J13: 67
... A26: 5023 | B26: Neha | C26: Pune | D26: IT | E26: Referral | F26: Joined | G26: 46191 | H26: 540000 | I26: 3 | J26: 87

Sheet Data Copy
A1: Employee ID | B1: Employee Name | C1: City | D1: Department | E1: Source | F1: Status | G1: Joining Date | H1: Salary | I1: Experience | J1: Performance | K1: Duplicate Flag | L1: Experience Category | M1: Performance Category | N1: Salary Category | O1: Referral Incentive | P1: Joining Month | Q1: Joining Year
A2: 5001 | B2: Anu | C2: Bangalore | D2: IT | E2: Naukri | F2: Joined | G2: 46027 | H2: 420000 | I2: 1 | J2: 82 | K2: =IF(COUNTIF($A$2:$A$26,A2)>1,"Duplicate","Unique") -> Unique | L2: {=_xlfn.IFS(OR(I2=1,I2=0),"Fresher",OR(I2=2,I2=3),"Imtermediate",I2>3,"Experienced")} -> Fresher | M2: {=_xlfn.IFS(J2<70,"Need Improvement",J2>89,"Excellent",J2>79,"Good",J2>69,"Average")} -> Good | N2: {=_xlfn.IFS(H2>499999,"High",H2>399999,"Medium",H2<400000,"Low")} -> Medium | O2: {=_xlfn.IFS(OR(E2="Naukri",E2="LinkedIn"),2%,E2="Referral",5%,E2="Walk-in",1%)} -> 0.02 | P2: {=MONTH(G2:G26)} -> 1 | Q2: {=YEAR(G2:G26)} -> 2026
A3: 5002 | B3: Rahul | C3: Chennai | D3: Finance | E3: Referral | F3: Joined | G3: 46034 | H3: 380000 | I3: 2 | J3: 76 | K3: =IF(COUNTIF($A$2:$A$26,A3)>1,"Duplicate","Unique") -> Unique | L3: {=_xlfn.IFS(OR(I3=1,I3=0),"Fresher",OR(I3=2,I3=3),"Imtermediate",I3>3,"Experienced")} -> Imtermediate | M3: {=_xlfn.IFS(J3<70,"Need Improvement",J3>89,"Excellent",J3>79,"Good",J3>69,"Average")} -> Average | N3: {=_xlfn.IFS(H3>499999,"High",H3>399999,"Medium",H3<400000,"Low")} -> Low | O3: {=_xlfn.IFS(OR(E3="Naukri",E3="LinkedIn"),2%,E3="Referral",5%,E3="Walk-in",1%)} -> 0.05 | P3: 1 | Q3: 2026
A4: 5003 | B4: Priya | C4: Bangalore | D4: HR | E4: LinkedIn | F4: Pending | G4: 46040 | H4: 350000 | I4: 1 | J4: 88 | K4: =IF(COUNTIF($A$2:$A$26,A4)>1,"Duplicate","Unique") -> Unique | L4: {=_xlfn.IFS(OR(I4=1,I4=0),"Fresher",OR(I4=2,I4=3),"Imtermediate",I4>3,"Experienced")} -> Fresher | M4: {=_xlfn.IFS(J4<70,"Need Improvement",J4>89,"Excellent",J4>79,"Good",J4>69,"Average")} -> Good | N4: {=_xlfn.IFS(H4>499999,"High",H4>399999,"Medium",H4<400000,"Low")} -> Low | O4: {=_xlfn.IFS(OR(E4="Naukri",E4="LinkedIn"),2%,E4="Referral",5%,E4="Walk-in",1%)} -> 0.02 | P4: 1 | Q4: 2026
A5: 5004 | B5: Kiran | C5: Hyderabad | D5: IT | E5: Naukri | F5: Joined | G5: 46044 | H5: 550000 | I5: 3 | J5: 91 | K5: =IF(COUNTIF($A$2:$A$26,A5)>1,"Duplicate","Unique") -> Unique | L5: {=_xlfn.IFS(OR(I5=1,I5=0),"Fresher",OR(I5=2,I5=3),"Imtermediate",I5>3,"Experienced")} -> Imtermediate | M5: {=_xlfn.IFS(J5<70,"Need Improvement",J5>89,"Excellent",J5>79,"Good",J5>69,"Average")} -> Excellent | N5: {=_xlfn.IFS(H5>499999,"High",H5>399999,"Medium",H5<400000,"Low")} -> High | O5: {=_xlfn.IFS(OR(E5="Naukri",E5="LinkedIn"),2%,E5="Referral",5%,E5="Walk-in",1%)} -> 0.02 | P5: 1 | Q5: 2026
A6: 5005 | B6: Sneha | C6: Bangalore | D6: Finance | E6: Referral | F6: Rejected | G6: 46051 | H6: 400000 | I6: 2 | J6: 69 | K6: =IF(COUNTIF($A$2:$A$26,A6)>1,"Duplicate","Unique") -> Duplicate | L6: {=_xlfn.IFS(OR(I6=1,I6=0),"Fresher",OR(I6=2,I6=3),"Imtermediate",I6>3,"Experienced")} -> Imtermediate | M6: {=_xlfn.IFS(J6<70,"Need Improvement",J6>89,"Excellent",J6>79,"Good",J6>69,"Average")} -> Need Improvement | N6: {=_xlfn.IFS(H6>499999,"High",H6>399999,"Medium",H6<400000,"Low")} -> Medium | O6: {=_xlfn.IFS(OR(E6="Naukri",E6="LinkedIn"),2%,E6="Referral",5%,E6="Walk-in",1%)} -> 0.05 | P6: 1 | Q6: 2026
A7: 5006 | B7: Arjun | C7: Pune | D7: IT | E7: LinkedIn | F7: Joined | G7: 46056 | H7: 600000 | I7: 4 | J7: 95 | K7: =IF(COUNTIF($A$2:$A$26,A7)>1,"Duplicate","Unique") -> Unique | L7: {=_xlfn.IFS(OR(I7=1,I7=0),"Fresher",OR(I7=2,I7=3),"Imtermediate",I7>3,"Experienced")} -> Experienced | M7: {=_xlfn.IFS(J7<70,"Need Improvement",J7>89,"Excellent",J7>79,"Good",J7>69,"Average")} -> Excellent | N7: {=_xlfn.IFS(H7>499999,"High",H7>399999,"Medium",H7<400000,"Low")} -> High | O7: {=_xlfn.IFS(OR(E7="Naukri",E7="LinkedIn"),2%,E7="Referral",5%,E7="Walk-in",1%)} -> 0.02 | P7: 2 | Q7: 2026
A8: 5007 | B8: Divya | C8: Bangalore | D8: Operations | E8: Walk-in | F8: Pending | G8: 46063 | H8: 320000 | I8: 1 | J8: 73 | K8: =IF(COUNTIF($A$2:$A$26,A8)>1,"Duplicate","Unique") -> Unique | L8: {=_xlfn.IFS(OR(I8=1,I8=0),"Fresher",OR(I8=2,I8=3),"Imtermediate",I8>3,"Experienced")} -> Fresher | M8: {=_xlfn.IFS(J8<70,"Need Improvement",J8>89,"Excellent",J8>79,"Good",J8>69,"Average")} -> Average | N8: {=_xlfn.IFS(H8>499999,"High",H8>399999,"Medium",H8<400000,"Low")} -> Low | O8: {=_xlfn.IFS(OR(E8="Naukri",E8="LinkedIn"),2%,E8="Referral",5%,E8="Walk-in",1%)} -> 0.01 | P8: 2 | Q8: 2026
A9: 5008 | B9: Manoj | C9: Chennai | D9: IT | E9: Naukri | F9: Joined | G9: 46070 | H9: 480000 | I9: 2 | J9: 84 | K9: =IF(COUNTIF($A$2:$A$26,A9)>1,"Duplicate","Unique") -> Unique | L9: {=_xlfn.IFS(OR(I9=1,I9=0),"Fresher",OR(I9=2,I9=3),"Imtermediate",I9>3,"Experienced")} -> Imtermediate | M9: {=_xlfn.IFS(J9<70,"Need Improvement",J9>89,"Excellent",J9>79,"Good",J9>69,"Average")} -> Good | N9: {=_xlfn.IFS(H9>499999,"High",H9>399999,"Medium",H9<400000,"Low")} -> Medium | O9: {=_xlfn.IFS(OR(E9="Naukri",E9="LinkedIn"),2%,E9="Referral",5%,E9="Walk-in",1%)} -> 0.02 | P9: 2 | Q9: 2026
A10: 5009 | B10: Kavya | C10: Bangalore | D10: HR | E10: Referral | F10: Joined | G10: 46077 | H10: 390000 | I10: 2 | J10: 79 | K10: =IF(COUNTIF($A$2:$A$26,A10)>1,"Duplicate","Unique") -> Unique | L10: {=_xlfn.IFS(OR(I10=1,I10=0),"Fresher",OR(I10=2,I10=3),"Imtermediate",I10>3,"Experienced")} -> Imtermediate | M10: {=_xlfn.IFS(J10<70,"Need Improvement",J10>89,"Excellent",J10>79,"Good",J10>69,"Average")} -> Average | N10: {=_xlfn.IFS(H10>499999,"High",H10>399999,"Medium",H10<400000,"Low")} -> Low | O10: {=_xlfn.IFS(OR(E10="Naukri",E10="LinkedIn"),2%,E10="Referral",5%,E10="Walk-in",1%)} -> 0.05 | P10: 2 | Q10: 2026
A11: 5010 | B11: Suresh | C11: Hyderabad | D11: Finance | E11: LinkedIn | F11: Rejected | G11: 46084 | H11: 450000 | I11: 3 | J11: 71 | K11: =IF(COUNTIF($A$2:$A$26,A11)>1,"Duplicate","Unique") -> Unique | L11: {=_xlfn.IFS(OR(I11=1,I11=0),"Fresher",OR(I11=2,I11=3),"Imtermediate",I11>3,"Experienced")} -> Imtermediate | M11: {=_xlfn.IFS(J11<70,"Need Improvement",J11>89,"Excellent",J11>79,"Good",J11>69,"Average")} -> Average | N11: {=_xlfn.IFS(H11>499999,"High",H11>399999,"Medium",H11<400000,"Low")} -> Medium | O11: {=_xlfn.IFS(OR(E11="Naukri",E11="LinkedIn"),2%,E11="Referral",5%,E11="Walk-in",1%)} -> 0.02 | P11: 3 | Q11: 2026
A12: 5011 | B12: Meena | C12: Bangalore | D12: IT | E12: Naukri | F12: Joined | G12: 46092 | H12: 520000 | I12: 1 | J12: 89 | K12: =IF(COUNTIF($A$2:$A$26,A12)>1,"Duplicate","Unique") -> Unique | L12: {=_xlfn.IFS(OR(I12=1,I12=0),"Fresher",OR(I12=2,I12=3),"Imtermediate",I12>3,"Experienced")} -> Fresher | M12: {=_xlfn.IFS(J12<70,"Need Improvement",J12>89,"Excellent",J12>79,"Good",J12>69,"Average")} -> Good | N12: {=_xlfn.IFS(H12>499999,"High",H12>399999,"Medium",H12<400000,"Low")} -> High | O12: {=_xlfn.IFS(OR(E12="Naukri",E12="LinkedIn"),2%,E12="Referral",5%,E12="Walk-in",1%)} -> 0.02 | P12: 3 | Q12: 2026
A13: 5012 | B13: Ajay | C13: Pune | D13: Operations | E13: Referral | F13: Pending | G13: 46099 | H13: 340000 | I13: 2 | J13: 67 | K13: =IF(COUNTIF($A$2:$A$26,A13)>1,"Duplicate","Unique") -> Unique | L13: {=_xlfn.IFS(OR(I13=1,I13=0),"Fresher",OR(I13=2,I13=3),"Imtermediate",I13>3,"Experienced")} -> Imtermediate | M13: {=_xlfn.IFS(J13<70,"Need Improvement",J13>89,"Excellent",J13>79,"Good",J13>69,"Average")} -> Need Improvement | N13: {=_xlfn.IFS(H13>499999,"High",H13>399999,"Medium",H13<400000,"Low")} -> Low | O13: {=_xlfn.IFS(OR(E13="Naukri",E13="LinkedIn"),2%,E13="Referral",5%,E13="Walk-in",1%)} -> 0.05 | P13: 3 | Q13: 2026
A14: 5013 | B14: Lakshmi | C14: Bangalore | D14: Finance | E14: Walk-in | F14: Joined | G14: 46106 | H14: 410000 | I14: 3 | J14: 86 | K14: =IF(COUNTIF($A$2:$A$26,A14)>1,"Duplicate","Unique") -> Unique | L14: {=_xlfn.IFS(OR(I14=1,I14=0),"Fresher",OR(I14=2,I14=3),"Imtermediate",I14>3,"Experienced")} -> Imtermediate | M14: {=_xlfn.IFS(J14<70,"Need Improvement",J14>89,"Excellent",J14>79,"Good",J14>69,"Average")} -> Good | N14: {=_xlfn.IFS(H14>499999,"High",H14>399999,"Medium",H14<400000,"Low")} -> Medium | O14: {=_xlfn.IFS(OR(E14="Naukri",E14="LinkedIn"),2%,E14="Referral",5%,E14="Walk-in",1%)} -> 0.01 | P14: 3 | Q14: 2026
... A26: 5023 | B26: Neha | C26: Pune | D26: IT | E26: Referral | F26: Joined | G26: 46191 | H26: 540000 | I26: 3 | J26: 87 | K26: =IF(COUNTIF($A$2:$A$26,A26)>1,"Duplicate","Unique") -> Unique | L26: {=_xlfn.IFS(OR(I26=1,I26=0),"Fresher",OR(I26=2,I26=3),"Imtermediate",I26>3,"Experienced")} -> Imtermediate | M26: {=_xlfn.IFS(J26<70,"Need Improvement",J26>89,"Excellent",J26>79,"Good",J26>69,"Average")} -> Good | N26: {=_xlfn.IFS(H26>499999,"High",H26>399999,"Medium",H26<400000,"Low")} -> High | O26: {=_xlfn.IFS(OR(E26="Naukri",E26="LinkedIn"),2%,E26="Referral",5%,E26="Walk-in",1%)} -> 0.05 | P26: 6 | Q26: 2026

Sheet Assessment Instuctions
A1: PART 1 — Data Cleaning
A3: Q1
A5: Check the Employee ID column for duplicates and create:
A7: Duplicate Flag
A9: Mark each record as:
A11: Duplicate
A12: Unique
A14: Q2
A16: Create:
A18: Experience Category
A20: Rules:
A22: 0–1 years → Fresher
... A26: Q3
A28: Check whether there are any blank cells in the dataset. | E28: NO Blank
A30: If there are, identify the column and handle them appropriately.
A34: PART 2 — Conditional Logic
A36: Q4
A38: Create:
A40: Performance Category
A42: Rules:
A44: 90 or above → Excellent
A45: 80–89 → Good
A46: 70–79 → Average
A47: Below 70 → Needs Improvement
A49: Q5
A51: Create:
... A78: Q7
A80: How many employees are from Bangalore? | D80: =COUNTIFS('Data Copy'!K2:K26,'Data Copy'!$K$2,'Data Copy'!C2:C26,'Data Copy'!$C$2) -> 11
A82: Q8
A84: How many employees are from Bangalore AND IT? | E84: =COUNTIFS('Data Copy'!K2:K26,'Data Copy'!$K$2,'Data Copy'!C2:C26,'Data Copy'!$C$2,'Data Copy'!D2:D26,'Data Copy'!$D$2) -> 3
A86: Q9
A88: How many employees are:
A90: Bangalore + Joined | C90: =COUNTIFS('Data Copy'!K2:K26,'Data Copy'!$K$2,'Data Copy'!C2:C26,'Data Copy'!$C$2,'Data Copy'!F2:F26,'Data Copy'!$F$2) -> 7
A92: Q10
A94: How many employees came through Referral and are Joined? | E94: =COUNTIFS('Data Copy'!K2:K26,'Data Copy'!$K$2,'Data Copy'!E2:E26,'Data Copy'!$E$3,'Data Copy'!F2:F26,'Data Copy'!$F$2) -> 4
A96: Q11
A98: How many employees have Performance >= 85? | D98: =COUNTIF('Data Copy'!J2:J26,">=85") -> 11
A102: PART 4 — SUM / AVERAGE
A104: Q12
A106: Find the total salary of all employees. | D106: =SUM('Data Copy'!H2:H26) -> 11170000
...

Sheet Data Validation
A1: Validation List (Source)
A2: City | B2: Department | C2: Status
A3: {=_xlfn.UNIQUE('Data Copy'!C2:C26,FALSE,FALSE)} -> Bangalore | B3: {=_xlfn.UNIQUE('Data Copy'!D2:D26,FALSE,FALSE)} -> IT | C3: {=_xlfn.UNIQUE('Data Copy'!F2:F26)} -> Joined
A4: Chennai | B4: Finance | C4: Pending
A5: Hyderabad | B5: HR | C5: Rejected
A6: Pune | B6: Operations
B9: Data Validation
B11: City | C11: Department | D11: Status
